Workbook

Sheet Portal Uploads Report
A1: PORTAL UPLOADS REPORT — Sep - 26
A4: Sep - 26 SUMMARY | D4: RESOLUTION TIME BY MONTH (last 3 months)
A5: Uploads in month | B5: =COUNTIF('Data (calc)'!$J$2:$J$253,"2026-09") | D5: Month | E5: # Uploads | F5: Resolved | G5: Avg. hours | H5: Avg. days | I5: % same day
A6: Resolved | B6: =COUNTIFS('Data (calc)'!$J$2:$J$253,"2026-09",'Data (calc)'!$H$2:$H$253,">=0") | D6: Jul - 26 | E6: =COUNTIF('Data (calc)'!$J$2:$J$253,"2026-07") | F6: =COUNTIFS('Data (calc)'!$J$2:$J$253,"2026-07",'Data (calc)'!$H$2:$H$253,">=0") | G6: =IFERROR(ROUND(AVERAGEIF('Data (calc)'!$J$2:$J$253,"2026-07",'Data (calc)'!$H$2:$H$253),1),0) | H6: =IFERROR(ROUND(AVERAGEIF('Data (calc)'!$J$2:$J$253,"2026-07",'Data (calc)'!$I$2:$I$253),1),0) | I6: =IFERROR(COUNTIFS('Data (calc)'!$J$2:$J$253,"2026-07",'Data (calc)'!$H$2:$H$253,"<24")/COUNTIFS('Data (calc)'!$J$2:$J$253,"2026-07",'Data (calc)'!$H$2:$H$253,">=0"),0)
A7: Avg. resolution (days) | B7: =IFERROR(ROUND(AVERAGEIF('Data (calc)'!$J$2:$J$253,"2026-09",'Data (calc)'!$I$2:$I$253),1),0) | D7: Aug - 26 | E7: =COUNTIF('Data (calc)'!$J$2:$J$253,"2026-08") | F7: =COUNTIFS('Data (calc)'!$J$2:$J$253,"2026-08",'Data (calc)'!$H$2:$H$253,">=0") | G7: =IFERROR(ROUND(AVERAGEIF('Data (calc)'!$J$2:$J$253,"2026-08",'Data (calc)'!$H$2:$H$253),1),0) | H7: =IFERROR(ROUND(AVERAGEIF('Data (calc)'!$J$2:$J$253,"2026-08",'Data (calc)'!$I$2:$I$253),1),0) | I7: =IFERROR(COUNTIFS('Data (calc)'!$J$2:$J$253,"2026-08",'Data (calc)'!$H$2:$H$253,"<24")/COUNTIFS('Data (calc)'!$J$2:$J$253,"2026-08",'Data (calc)'!$H$2:$H$253,">=0"),0)
A8: % same day | B8: =IFERROR(COUNTIFS('Data (calc)'!$J$2:$J$253,"2026-09",'Data (calc)'!$H$2:$H$253,"<24")/COUNTIFS('Data (calc)'!$J$2:$J$253,"2026-09",'Data (calc)'!$H$2:$H$253,">=0"),0) | D8: Sep - 26 | E8: =COUNTIF('Data (calc)'!$J$2:$J$253,"2026-09") | F8: =COUNTIFS('Data (calc)'!$J$2:$J$253,"2026-09",'Data (calc)'!$H$2:$H$253,">=0") | G8: =IFERROR(ROUND(AVERAGEIF('Data (calc)'!$J$2:$J$253,"2026-09",'Data (calc)'!$H$2:$H$253),1),0) | H8: =IFERROR(ROUND(AVERAGEIF('Data (calc)'!$J$2:$J$253,"2026-09",'Data (calc)'!$I$2:$I$253),1),0) | I8: =IFERROR(COUNTIFS('Data (calc)'!$J$2:$J$253,"2026-09",'Data (calc)'!$H$2:$H$253,"<24")/COUNTIFS('Data (calc)'!$J$2:$J$253,"2026-09",'Data (calc)'!$H$2:$H$253,">=0"),0)
A9: Open (not resolved) at month-end | B9: =COUNTIFS('Data (calc)'!$B$2:$B$253,"OPEN",'Data (calc)'!$J$2:$J$253,"2026-09") | D9: TOTAL | E9: =SUM(E6:E8) | F9: =SUM(F6:F8) | G9: =IFERROR(ROUND(AVERAGEIFS('Data (calc)'!$H$2:$H$253,'Data (calc)'!$J$2:$J$253,">=2026-07"),1),0) | H9: =IFERROR(ROUND(AVERAGEIFS('Data (calc)'!$I$2:$I$253,'Data (calc)'!$J$2:$J$253,">=2026-07"),1),0) | I9: =IFERROR(COUNTIFS('Data (calc)'!$J$2:$J$253,">=2026-07",'Data (calc)'!$H$2:$H$253,"<24")/COUNTIFS('Data (calc)'!$J$2:$J$253,">=2026-07",'Data (calc)'!$H$2:$H$253,">=0"),0)
A10: Portals used (month) | B10: 18
A15: RESOLUTION TIME DISTRIBUTION — Sep - 26 | D15: UPLOADS BY PORTAL — Sep - 26
A16: Range | B16: # Uploads | C16: % of total | D16: Portal | E16: # Uploads | F16: % of total | G16: Avg. days | H16: % same day
A17: Same day (< 24 h) | B17: =COUNTIFS('Data (calc)'!$J$2:$J$253,"2026-09",'Data (calc)'!$H$2:$H$253,"<24") | C17: =IFERROR(B17/COUNTIFS('Data (calc)'!$J$2:$J$253,"2026-09",'Data (calc)'!$H$2:$H$253,">=0"),0) | D17: Coupa | E17: =COUNTIFS('Data (calc)'!$C$2:$C$253,"Coupa",'Data (calc)'!$J$2:$J$253,"2026-09") | F17: =IFERROR(COUNTIFS('Data (calc)'!$C$2:$C$253,"Coupa",'Data (calc)'!$J$2:$J$253,"2026-09")/COUNTIF('Data (calc)'!$J$2:$J$253,"2026-09"),0) | G17: =IFERROR(ROUND(AVERAGEIFS('Data (calc)'!$I$2:$I$253,'Data (calc)'!$C$2:$C$253,"Coupa",'Data (calc)'!$J$2:$J$253,"2026-09"),1),0) | H17: =IFERROR(COUNTIFS('Data (calc)'!$C$2:$C$253,"Coupa",'Data (calc)'!$J$2:$J$253,"2026-09",'Data (calc)'!$H$2:$H$253,"<24")/COUNTIFS('Data (calc)'!$C$2:$C$253,"Coupa",'Data (calc)'!$J$2:$J$253,"2026-09",'Data (calc)'!$H$2:$H$253,">=0"),0)
A18: 1 – 2 days | B18: =COUNTIFS('Data (calc)'!$J$2:$J$253,"2026-09",'Data (calc)'!$H$2:$H$253,">=24",'Data (calc)'!$H$2:$H$253,"<48") | C18: =IFERROR(B18/COUNTIFS('Data (calc)'!$J$2:$J$253,"2026-09",'Data (calc)'!$H$2:$H$253,">=0"),0) | D18: Ariba | E18: =COUNTIFS('Data (calc)'!$C$2:$C$253,"Ariba",'Data (calc)'!$J$2:$J$253,"2026-09") | F18: =IFERROR(COUNTIFS('Data (calc)'!$C$2:$C$253,"Ariba",'Data (calc)'!$J$2:$J$253,"2026-09")/COUNTIF('Data (calc)'!$J$2:$J$253,"2026-09"),0) | G18: =IFERROR(ROUND(AVERAGEIFS('Data (calc)'!$I$2:$I$253,'Data (calc)'!$C$2:$C$253,"Ariba",'Data (calc)'!$J$2:$J$253,"2026-09"),1),0) | H18: =IFERROR(COUNTIFS('Data (calc)'!$C$2:$C$253,"Ariba",'Data (calc)'!$J$2:$J$253,"2026-09",'Data (calc)'!$H$2:$H$253,"<24")/COUNTIFS('Data (calc)'!$C$2:$C$253,"Ariba",'Data (calc)'!$J$2:$J$253,"2026-09",'Data (calc)'!$H$2:$H$253,">=0"),0)
A19: 2 – 4 days | B19: =COUNTIFS('Data (calc)'!$J$2:$J$253,"2026-09",'Data (calc)'!$H$2:$H$253,">=48",'Data (calc)'!$H$2:$H$253,"<96") | C19: =IFERROR(B19/COUNTIFS('Data (calc)'!$J$2:$J$253,"2026-09",'Data (calc)'!$H$2:$H$253,">=0"),0) | D19: Taulia | E19: =COUNTIFS('Data (calc)'!$C$2:$C$253,"Taulia",'Data (calc)'!$J$2:$J$253,"2026-09") | F19: =IFERROR(COUNTIFS('Data (calc)'!$C$2:$C$253,"Taulia",'Data (calc)'!$J$2:$J$253,"2026-09")/COUNTIF('Data (calc)'!$J$2:$J$253,"2026-09"),0) | G19: =IFERROR(ROUND(AVERAGEIFS('Data (calc)'!$I$2:$I$253,'Data (calc)'!$C$2:$C$253,"Taulia",'Data (calc)'!$J$2:$J$253,"2026-09"),1),0) | H19: =IFERROR(COUNTIFS('Data (calc)'!$C$2:$C$253,"Taulia",'Data (calc)'!$J$2:$J$253,"2026-09",'Data (calc)'!$H$2:$H$253,"<24")/COUNTIFS('Data (calc)'!$C$2:$C$253,"Taulia",'Data (calc)'!$J$2:$J$253,"2026-09",'Data (calc)'!$H$2:$H$253,">=0"),0)
A20: 4 – 7 days | B20: =COUNTIFS('Data (calc)'!$J$2:$J$253,"2026-09",'Data (calc)'!$H$2:$H$253,">=96",'Data (calc)'!$H$2:$H$253,"<168") | C20: =IFERROR(B20/COUNTIFS('Data (calc)'!$J$2:$J$253,"2026-09",'Data (calc)'!$H$2:$H$253,">=0"),0) | D20: URL | E20: =COUNTIFS('Data (calc)'!$C$2:$C$253,"URL",'Data (calc)'!$J$2:$J$253,"2026-09") | F20: =IFERROR(COUNTIFS('Data (calc)'!$C$2:$C$253,"URL",'Data (calc)'!$J$2:$J$253,"2026-09")/COUNTIF('Data (calc)'!$J$2:$J$253,"2026-09"),0) | G20: =IFERROR(ROUND(AVERAGEIFS('Data (calc)'!$I$2:$I$253,'Data (calc)'!$C$2:$C$253,"URL",'Data (calc)'!$J$2:$J$253,"2026-09"),1),0) | H20: =IFERROR(COUNTIFS('Data (calc)'!$C$2:$C$253,"URL",'Data (calc)'!$J$2:$J$253,"2026-09",'Data (calc)'!$H$2:$H$253,"<24")/COUNTIFS('Data (calc)'!$C$2:$C$253,"URL",'Data (calc)'!$J$2:$J$253,"2026-09",'Data (calc)'!$H$2:$H$253,">=0"),0)
A21: More than 7 days | B21: =COUNTIFS('Data (calc)'!$J$2:$J$253,"2026-09",'Data (calc)'!$H$2:$H$253,">=168") | C21: =IFERROR(B21/COUNTIFS('Data (calc)'!$J$2:$J$253,"2026-09",'Data (calc)'!$H$2:$H$253,">=0"),0) | D21: Chorus Pro | E21: =COUNTIFS('Data (calc)'!$C$2:$C$253,"Chorus Pro",'Data (calc)'!$J$2:$J$253,"2026-09") | F21: =IFERROR(COUNTIFS('Data (calc)'!$C$2:$C$253,"Chorus Pro",'Data (calc)'!$J$2:$J$253,"2026-09")/COUNTIF('Data (calc)'!$J$2:$J$253,"2026-09"),0) | G21: =IFERROR(ROUND(AVERAGEIFS('Data (calc)'!$I$2:$I$253,'Data (calc)'!$C$2:$C$253,"Chorus Pro",'Data (calc)'!$J$2:$J$253,"2026-09"),1),0) | H21: =IFERROR(COUNTIFS('Data (calc)'!$C$2:$C$253,"Chorus Pro",'Data (calc)'!$J$2:$J$253,"2026-09",'Data (calc)'!$H$2:$H$253,"<24")/COUNTIFS('Data (calc)'!$C$2:$C$253,"Chorus Pro",'Data (calc)'!$J$2:$J$253,"2026-09",'Data (calc)'!$H$2:$H$253,">=0"),0)
A22: TOTAL | B22: =SUM(B17:B21) | C22: =IFERROR(B22/COUNTIFS('Data (calc)'!$J$2:$J$253,"2026-09",'Data (calc)'!$H$2:$H$253,">=0"),0) | D22: Oracle | E22: =COUNTIFS('Data (calc)'!$C$2:$C$253,"Oracle",'Data (calc)'!$J$2:$J$253,"2026-09") | F22: =IFERROR(COUNTIFS('Data (calc)'!$C$2:$C$253,"Oracle",'Data (calc)'!$J$2:$J$253,"2026-09")/COUNTIF('Data (calc)'!$J$2:$J$253,"2026-09"),0) | G22: =IFERROR(ROUND(AVERAGEIFS('Data (calc)'!$I$2:$I$253,'Data (calc)'!$C$2:$C$253,"Oracle",'Data (calc)'!$J$2:$J$253,"2026-09"),1),0) | H22: =IFERROR(COUNTIFS('Data (calc)'!$C$2:$C$253,"Oracle",'Data (calc)'!$J$2:$J$253,"2026-09",'Data (calc)'!$H$2:$H$253,"<24")/COUNTIFS('Data (calc)'!$C$2:$C$253,"Oracle",'Data (calc)'!$J$2:$J$253,"2026-09",'Data (calc)'!$H$2:$H$253,">=0"),0)
D23: Ivalua | E23: =COUNTIFS('Data (calc)'!$C$2:$C$253,"Ivalua",'Data (calc)'!$J$2:$J$253,"2026-09") | F23: =IFERROR(COUNTIFS('Data (calc)'!$C$2:$C$253,"Ivalua",'Data (calc)'!$J$2:$J$253,"2026-09")/COUNTIF('Data (calc)'!$J$2:$J$253,"2026-09"),0) | G23: =IFERROR(ROUND(AVERAGEIFS('Data (calc)'!$I$2:$I$253,'Data (calc)'!$C$2:$C$253,"Ivalua",'Data (calc)'!$J$2:$J$253,"2026-09"),1),0) | H23: =IFERROR(COUNTIFS('Data (calc)'!$C$2:$C$253,"Ivalua",'Data (calc)'!$J$2:$J$253,"2026-09",'Data (calc)'!$H$2:$H$253,"<24")/COUNTIFS('Data (calc)'!$C$2:$C$253,"Ivalua",'Data (calc)'!$J$2:$J$253,"2026-09",'Data (calc)'!$H$2:$H$253,">=0"),0)
D24: Vendors@Gov | E24: =COUNTIFS('Data (calc)'!$C$2:$C$253,"Vendors@Gov",'Data (calc)'!$J$2:$J$253,"2026-09") | F24: =IFERROR(COUNTIFS('Data (calc)'!$C$2:$C$253,"Vendors@Gov",'Data (calc)'!$J$2:$J$253,"2026-09")/COUNTIF('Data (calc)'!$J$2:$J$253,"2026-09"),0) | G24: =IFERROR(ROUND(AVERAGEIFS('Data (calc)'!$I$2:$I$253,'Data (calc)'!$C$2:$C$253,"Vendors@Gov",'Data (calc)'!$J$2:$J$253,"2026-09"),1),0) | H24: =IFERROR(COUNTIFS('Data (calc)'!$C$2:$C$253,"Vendors@Gov",'Data (calc)'!$J$2:$J$253,"2026-09",'Data (calc)'!$H$2:$H$253,"<24")/COUNTIFS('Data (calc)'!$C$2:$C$253,"Vendors@Gov",'Data (calc)'!$J$2:$J$253,"2026-09",'Data (calc)'!$H$2:$H$253,">=0"),0)
D25: Other | E25: 11 | F25: =IFERROR(E25/COUNTIF('Data (calc)'!$J$2:$J$253,"2026-09"),0) | G25: 0.2 | H25: 1
D26: TOTAL | E26: =COUNTIF('Data (calc)'!$J$2:$J$253,"2026-09") | F26: =IFERROR(E26/COUNTIF('Data (calc)'!$J$2:$J$253,"2026-09"),0) | G26: =IFERROR(ROUND(AVERAGEIF('Data (calc)'!$J$2:$J$253,"2026-09",'Data (calc)'!$I$2:$I$253),1),0) | H26: =IFERROR(COUNTIFS('Data (calc)'!$J$2:$J$253,"2026-09",'Data (calc)'!$H$2:$H$253,"<24")/COUNTIFS('Data (calc)'!$J$2:$J$253,"2026-09",'Data (calc)'!$H$2:$H$253,">=0"),0)

Sheet Data (calc)
A1: Invoice Number | B1: Status | C1: Portal (norm.) | D1: Submitted By | E1: Collector assigned | F1: Submit Timestamp | G1: Resolved Timestamp | H1: Resolution (hrs) | I1: Resolution (days) | J1: Month | K1: Days open
A2: test | B2: OPEN | C2: Other | D2: Alejandra Mendoza | F2: 46013.894 | J2: 2025-12 | K2: 282
A3: QILNEW1915 | B3: RESOLVED | C3: Bmw Portal | D3: Alejandra Mendoza | E3: @dreimers | F3: 46175.574 | G3: 46176.467 | H3: 21.4 | I3: 0.9 | J3: 2026-06
A4: INV00020111 | B4: RESOLVED | C4: Ariba | D4: Daniela Gomez Viscaino | E4: @dreimers | F4: 46176.435 | G4: 46176.566 | H4: 3.1 | I4: 0.1 | J4: 2026-06
A5: Not Generated | B5: RESOLVED | C5: Chorus Pro | D5: Kaushal Hogade | E5: @dreimers | F5: 46176.463 | G5: 46177.526 | H5: 25.5 | I5: 1.1 | J5: 2026-06
A6: INV00019964 | B6: RESOLVED | C6: Coupa | D6: Daniela Gomez Viscaino | E6: @dreimers | F6: 46176.569 | G6: 46177.513 | H6: 22.7 | I6: 0.9 | J6: 2026-06
A7: 469020 | B7: RESOLVED | C7: Ariba | D7: Maria Granja | E7: @dreimers | F7: 46177.634 | G7: 46178.419 | H7: 18.8 | I7: 0.8 | J7: 2026-06
A8: 468868 | B8: RESOLVED | C8: Ariba | D8: Ashley Hudson | E8: @dreimers | F8: 46177.952 | G8: 46197.54 | H8: 470.1 | I8: 19.6 | J8: 2026-06
A9: INV00020070 / INV00020071 / INV00020069 / 469136 | B9: RESOLVED | C9: Taulia | D9: Ashley Hudson | E9: @dreimers | F9: 46178.051 | G9: 46178.564 | H9: 12.3 | I9: 0.5 | J9: 2026-06
B10: RESOLVED | C10: Ariba | D10: Pamella Covarrubias | E10: @dreimers | F10: 46178.565 | G10: 46178.607 | H10: 1 | I10: 0 | J10: 2026-06
A11: 466580 | B11: RESOLVED | C11: URL | D11: Nikhil Anjikar | E11: @dreimers | F11: 46178.588 | G11: 46183.649 | H11: 121.5 | I11: 5.1 | J11: 2026-06
A12: INV00020293 | B12: RESOLVED | C12: Google | D12: Daniela Gomez Viscaino | E12: @dreimers | F12: 46181.576 | G12: 46182.331 | H12: 18.1 | I12: 0.8 | J12: 2026-06
A13: unknown | B13: RESOLVED | C13: Coupa | D13: Eduardo Rivera | E13: @dreimers | F13: 46183.523 | G13: 46183.612 | H13: 2.1 | I13: 0.1 | J13: 2026-06
A14: 470660 | B14: RESOLVED | C14: Coupa | D14: Jose Novelo | E14: @dreimers | F14: 46183.683 | G14: 46197.545 | H14: 332.7 | I14: 13.9 | J14: 2026-06
A15: 470678 | B15: RESOLVED | C15: Awrostamani Port | D15: Jose Novelo | E15: @dreimers | F15: 46183.688 | G15: 46185.422 | H15: 41.6 | I15: 1.7 | J15: 2026-06
A16: 462239 | B16: RESOLVED | C16: Coupa | D16: Saiyon Tanaka | E16: @dreimers | F16: 46184.984 | G16: 46185.489 | H16: 12.1 | I16: 0.5 | J16: 2026-06
A17: INV00020633 | B17: RESOLVED | C17: Ariba | D17: Daniela Gomez Viscaino | E17: @dreimers | F17: 46185.519 | G17: 46197.547 | H17: 288.7 | I17: 12 | J17: 2026-06
A18: #464499 | B18: RESOLVED | C18: Ariba | D18: Emma Günther | E18: @dreimers | F18: 46188.126 | G18: 46192.575 | H18: 106.8 | I18: 4.4 | J18: 2026-06
A19: INV00020140 | B19: RESOLVED | C19: Peppol | D19: Fabrizio Rico del Mazo | E19: @dreimers | F19: 46188.434 | G19: 46197.551 | H19: 218.8 | I19: 9.1 | J19: 2026-06
A20: INV00020695 | B20: RESOLVED | C20: Ariba | D20: Daniela Gomez Viscaino | E20: @aprilj | F20: 46188.655 | G20: 46189.315 | H20: 15.9 | I20: 0.7 | J20: 2026-06
A21: INV00020722 | B21: RESOLVED | C21: Ariba | D21: Daniela Gomez Viscaino | E21: @aprilj | F21: 46188.659 | G21: 46189.318 | H21: 15.8 | I21: 0.7 | J21: 2026-06
A22: INV00020373 | B22: RESOLVED | C22: Coupa | D22: Daniela Gomez Viscaino | E22: @aprilj | F22: 46188.67 | G22: 46189.331 | H22: 15.9 | I22: 0.7 | J22: 2026-06
... A47: INV00021650 | B47: RESOLVED | C47: Coupa | D47: Maria de Lourdes López Núñez | E47: @dreimers | F47: 46198.49 | G47: 46198.574 | H47: 2 | I47: 0.1 | J47: 2026-06
A48: 470840 | B48: RESOLVED | C48: Chorus Pro | D48: Kaushal Hogade | F48: 46199.163 | G48: 46199.471 | H48: 7.4 | I48: 0.3 | J48: 2026-06
A49: 2D-21801766 | B49: RESOLVED | C49: Coupa | D49: Imanol Martinez | E49: @dreimers | F49: 46199.426 | G49: 46199.488 | H49: 1.5 | I49: 0.1 | J49: 2026-06
A50: INV00021939 | B50: RESOLVED | C50: Microsoft | D50: Andrea Juarez | E50: @dreimers | F50: 46201.952 | G50: 46202.547 | H50: 14.3 | I50: 0.6 | J50: 2026-06
A51: 4500114905 | B51: RESOLVED | C51: Chorus Pro | D51: Eleonora Amarante | E51: @dreimers | F51: 46202.438 | G51: 46202.518 | H51: 1.9 | I51: 0.1 | J51: 2026-06
A52: 471109 | B52: RESOLVED | C52: Coupa | D52: Fabrizio Rico del Mazo | E52: @kburkett | F52: 46202.515 | G52: 46202.621 | H52: 2.5 | I52: 0.1 | J52: 2026-06
A53: INV00021802 | B53: RESOLVED | C53: Ariba | D53: Daniela Gomez Viscaino | E53: @kburkett | F53: 46202.786 | G53: 46202.937 | H53: 3.6 | I53: 0.2 | J53: 2026-06
A54: INV00021701 | B54: RESOLVED | C54: Coupa | D54: Daniela Gomez Viscaino | E54: @kburkett | F54: 46202.788 | G54: 46202.917 | H54: 3.1 | I54: 0.1 | J54: 2026-06
A55: INV00021462 | B55: RESOLVED | C55: Ariba | D55: Daniela Gomez Viscaino | E55: @kburkett | F55: 46202.791 | G55: 46202.933 | H55: 3.4 | I55: 0.1 | J55: 2026-06
A56: INV00021491 | B56: RESOLVED | C56: Coupa | D56: Daniela Gomez Viscaino | E56: @kburkett | F56: 46202.792 | G56: 46202.929 | H56: 3.3 | I56: 0.1 | J56: 2026-06
A57: INV00021769 | B57: RESOLVED | C57: Coupa | D57: Daniela Gomez Viscaino | E57: @kburkett | F57: 46202.794 | G57: 46210.341 | H57: 181.1 | I57: 7.5 | J57: 2026-06
A58: INV00021673 | B58: RESOLVED | C58: Taulia | D58: Ashley Hudson | E58: @kburkett | F58: 46202.822 | G58: 46202.9 | H58: 1.9 | I58: 0.1 | J58: 2026-06
A59: INV00022143 | B59: RESOLVED | C59: Ariba | D59: Daniela Gomez Viscaino | E59: @dreimers | F59: 46203.462 | G59: 46218.473 | H59: 360.3 | I59: 15 | J59: 2026-06
A60: INV00019962 | B60: RESOLVED | C60: Ariba | D60: Elías Chávez Zamorano | E60: @dreimers | F60: 46203.552 | G60: 46204.506 | H60: 22.9 | I60: 1 | J60: 2026-06
... A79: 465391 | B79: RESOLVED | C79: Ariba | D79: George Kahy | E79: @dreimers | F79: 46212.958 | G79: 46213.498 | H79: 13 | I79: 0.5 | J79: 2026-07
B80: RESOLVED | C80: Other | D80: Andres Prieto | E80: @dreimers | F80: 46213.661 | G80: 46216.506 | H80: 68.3 | I80: 2.8 | J80: 2026-07
A81: 471288 | B81: RESOLVED | C81: Ariba | D81: Alejandro Salazar Copado | E81: @dreimers | F81: 46213.682 | G81: 46216.509 | H81: 67.8 | I81: 2.8 | J81: 2026-07
A82: 471302 | B82: RESOLVED | C82: Ariba | D82: Alejandro Salazar Copado | E82: @dreimers | F82: 46216.4 | G82: 46218.468 | H82: 49.6 | I82: 2.1 | J82: 2026-07
...

Sheet Open & In Progress
A1: OPEN AT Sep - 26 MONTH-END — not resolved by month-end
A3: Invoice Number | B3: Portal | C3: Submitted By | D3: Collector assigned | E3: Submit Timestamp | F3: Days open
A4: 472138 | B4: Ariba | C4: Alejandro Salazar Copado | D4: @dreimers | E4: 46269.699 | F4: 26
A5: INV00027000 | B5: URL | C5: Viki Kovaliv | D5: @dreimers | E5: 46273.381 | F5: 22
A6: INV00027789 | B6: Ariba | C6: Hinata Igawa | E6: 46276.002 | F6: 19
A7: INV00027927 | B7: Ariba | C7: Hinata Igawa | E7: 46276.023 | F7: 19
A8: INV00028223 | B8: Peppol | C8: Rosario Flores | D8: @dreimers | E8: 46276.641 | F8: 19
A9: 466580 | B9: Vendors@Gov | C9: George Kahy | D9: @dreimers | E9: 46282.876 | F9: 13
A10: INV00028076 | B10: Coupa | C10: Viki Kovaliv | D10: @dreimers | E10: 46286.391 | F10: 9
A11: 471600 | B11: Oracle | C11: Viki Kovaliv | D11: @dreimers | E11: 46288.367 | F11: 7
A12: INV00027503 | B12: Coupa | C12: Daniela Gomez Viscaino | D12: @dreimers | E12: 46294.654 | F12: 1
A13: INV00027611 | B13: Ariba | C13: Daniela Gomez Viscaino | D13: @dreimers | E13: 46294.658 | F13: 1
A14: INV00029328 | B14: John Deere E-Inv | C14: Daniela Gomez Viscaino | D14: @dreimers | E14: 46294.662 | F14: 1
A15: INV00029332 | B15: Siemens | C15: Maria de Lourdes López Núñez | D15: @dreimers | E15: 46295.485 | F15: 0

Sheet Slow Uploads Sep - 26 (>2d)
A1: Sep - 26 UPLOADS RESOLVED IN MORE THAN 2 DAYS
A3: Invoice Number | B3: Portal | C3: Submitted By | D3: Collector assigned | E3: Submit Timestamp | F3: Resolved Timestamp | G3: Resolution days
A4: 470826 | B4: Chorus Pro | C4: Gabriela Kwaśniewska | D4: @dreimers | E4: 46268.343 | F4: 46289.798 | G4: =(F4-E4)
