Workbook

Sheet Reporte Agosto 2026
A1: REPORTE DE PORTAL UPLOADS — AGOSTO 2026
A2: Resolution Time = Resolved − Submit. Distribución y portal filtrados a agosto; la tabla mensual muestra todos los meses.
A4: RESOLUTION TIME POR MES
A5: Mes | B5: # Uploads | C5: Resueltos | D5: Prom. horas | E5: Prom. días | F5: % mismo día
A6: 2026-06 | B6: =COUNTIF('Datos (calculo)'!$H$2:$H$169,"2026-06") | C6: =COUNTIFS('Datos (calculo)'!$H$2:$H$169,"2026-06",'Datos (calculo)'!$F$2:$F$169,">=0") | D6: =IFERROR(ROUND(AVERAGEIF('Datos (calculo)'!$H$2:$H$169,"2026-06",'Datos (calculo)'!$F$2:$F$169),1),0) | E6: =IFERROR(ROUND(AVERAGEIF('Datos (calculo)'!$H$2:$H$169,"2026-06",'Datos (calculo)'!$G$2:$G$169),1),0) | F6: =IFERROR(COUNTIFS('Datos (calculo)'!$H$2:$H$169,"2026-06",'Datos (calculo)'!$F$2:$F$169,"<24")/COUNTIFS('Datos (calculo)'!$H$2:$H$169,"2026-06",'Datos (calculo)'!$F$2:$F$169,">=0"),0)
A7: 2026-07 | B7: =COUNTIF('Datos (calculo)'!$H$2:$H$169,"2026-07") | C7: =COUNTIFS('Datos (calculo)'!$H$2:$H$169,"2026-07",'Datos (calculo)'!$F$2:$F$169,">=0") | D7: =IFERROR(ROUND(AVERAGEIF('Datos (calculo)'!$H$2:$H$169,"2026-07",'Datos (calculo)'!$F$2:$F$169),1),0) | E7: =IFERROR(ROUND(AVERAGEIF('Datos (calculo)'!$H$2:$H$169,"2026-07",'Datos (calculo)'!$G$2:$G$169),1),0) | F7: =IFERROR(COUNTIFS('Datos (calculo)'!$H$2:$H$169,"2026-07",'Datos (calculo)'!$F$2:$F$169,"<24")/COUNTIFS('Datos (calculo)'!$H$2:$H$169,"2026-07",'Datos (calculo)'!$F$2:$F$169,">=0"),0)
A8: 2026-08 | B8: =COUNTIF('Datos (calculo)'!$H$2:$H$169,"2026-08") | C8: =COUNTIFS('Datos (calculo)'!$H$2:$H$169,"2026-08",'Datos (calculo)'!$F$2:$F$169,">=0") | D8: =IFERROR(ROUND(AVERAGEIF('Datos (calculo)'!$H$2:$H$169,"2026-08",'Datos (calculo)'!$F$2:$F$169),1),0) | E8: =IFERROR(ROUND(AVERAGEIF('Datos (calculo)'!$H$2:$H$169,"2026-08",'Datos (calculo)'!$G$2:$G$169),1),0) | F8: =IFERROR(COUNTIFS('Datos (calculo)'!$H$2:$H$169,"2026-08",'Datos (calculo)'!$F$2:$F$169,"<24")/COUNTIFS('Datos (calculo)'!$H$2:$H$169,"2026-08",'Datos (calculo)'!$F$2:$F$169,">=0"),0)
A9: TOTAL | B9: =SUM(B6:B8) | C9: =SUM(C6:C8) | D9: =ROUND(AVERAGE('Datos (calculo)'!$F$2:$F$169),1) | E9: =ROUND(AVERAGE('Datos (calculo)'!$G$2:$G$169),1) | F9: =IFERROR(COUNTIFS('Datos (calculo)'!$F$2:$F$169,"<24")/COUNT('Datos (calculo)'!$F$2:$F$169),0)
A12: DISTRIBUCIÓN POR TIEMPO DE RESOLUCIÓN — AGOSTO
A13: Rango | B13: # Uploads | C13: % del total
A14: Mismo día (< 24 h) | B14: =COUNTIFS('Datos (calculo)'!$H$2:$H$169,"2026-08",'Datos (calculo)'!$F$2:$F$169,"<24") | C14: =IFERROR(B14/COUNTIFS('Datos (calculo)'!$H$2:$H$169,"2026-08",'Datos (calculo)'!$F$2:$F$169,">=0"),0)
A15: 1 – 2 días | B15: =COUNTIFS('Datos (calculo)'!$H$2:$H$169,"2026-08",'Datos (calculo)'!$F$2:$F$169,">=24",'Datos (calculo)'!$F$2:$F$169,"<48") | C15: =IFERROR(B15/COUNTIFS('Datos (calculo)'!$H$2:$H$169,"2026-08",'Datos (calculo)'!$F$2:$F$169,">=0"),0)
A16: 2 – 4 días | B16: =COUNTIFS('Datos (calculo)'!$H$2:$H$169,"2026-08",'Datos (calculo)'!$F$2:$F$169,">=48",'Datos (calculo)'!$F$2:$F$169,"<96") | C16: =IFERROR(B16/COUNTIFS('Datos (calculo)'!$H$2:$H$169,"2026-08",'Datos (calculo)'!$F$2:$F$169,">=0"),0)
A17: 4 – 7 días | B17: =COUNTIFS('Datos (calculo)'!$H$2:$H$169,"2026-08",'Datos (calculo)'!$F$2:$F$169,">=96",'Datos (calculo)'!$F$2:$F$169,"<168") | C17: =IFERROR(B17/COUNTIFS('Datos (calculo)'!$H$2:$H$169,"2026-08",'Datos (calculo)'!$F$2:$F$169,">=0"),0)
A18: Más de 7 días | B18: =COUNTIFS('Datos (calculo)'!$H$2:$H$169,"2026-08",'Datos (calculo)'!$F$2:$F$169,">=168") | C18: =IFERROR(B18/COUNTIFS('Datos (calculo)'!$H$2:$H$169,"2026-08",'Datos (calculo)'!$F$2:$F$169,">=0"),0)
A19: TOTAL | B19: =SUM(B14:B18) | C19: =IFERROR(B19/COUNTIFS('Datos (calculo)'!$H$2:$H$169,"2026-08",'Datos (calculo)'!$F$2:$F$169,">=0"),0)
A22: RESOLUTION TIME POR PORTAL — AGOSTO
A23: Portal | B23: # Uploads | C23: % del total | D23: Prom. días | E23: % mismo día
A24: Coupa | B24: =COUNTIFS('Datos (calculo)'!$I$2:$I$169,"Coupa",'Datos (calculo)'!$H$2:$H$169,"2026-08") | C24: =IFERROR(COUNTIFS('Datos (calculo)'!$I$2:$I$169,"Coupa",'Datos (calculo)'!$H$2:$H$169,"2026-08")/COUNTIFS('Datos (calculo)'!$H$2:$H$169,"2026-08",'Datos (calculo)'!$F$2:$F$169,">=0"),0) | D24: =IFERROR(ROUND(AVERAGEIFS('Datos (calculo)'!$G$2:$G$169,'Datos (calculo)'!$I$2:$I$169,"Coupa",'Datos (calculo)'!$H$2:$H$169,"2026-08"),1),0) | E24: =IFERROR(COUNTIFS('Datos (calculo)'!$I$2:$I$169,"Coupa",'Datos (calculo)'!$H$2:$H$169,"2026-08",'Datos (calculo)'!$F$2:$F$169,"<24")/COUNTIFS('Datos (calculo)'!$I$2:$I$169,"Coupa",'Datos (calculo)'!$H$2:$H$169,"2026-08"),0)
A25: Ariba | B25: =COUNTIFS('Datos (calculo)'!$I$2:$I$169,"Ariba",'Datos (calculo)'!$H$2:$H$169,"2026-08") | C25: =IFERROR(COUNTIFS('Datos (calculo)'!$I$2:$I$169,"Ariba",'Datos (calculo)'!$H$2:$H$169,"2026-08")/COUNTIFS('Datos (calculo)'!$H$2:$H$169,"2026-08",'Datos (calculo)'!$F$2:$F$169,">=0"),0) | D25: =IFERROR(ROUND(AVERAGEIFS('Datos (calculo)'!$G$2:$G$169,'Datos (calculo)'!$I$2:$I$169,"Ariba",'Datos (calculo)'!$H$2:$H$169,"2026-08"),1),0) | E25: =IFERROR(COUNTIFS('Datos (calculo)'!$I$2:$I$169,"Ariba",'Datos (calculo)'!$H$2:$H$169,"2026-08",'Datos (calculo)'!$F$2:$F$169,"<24")/COUNTIFS('Datos (calculo)'!$I$2:$I$169,"Ariba",'Datos (calculo)'!$H$2:$H$169,"2026-08"),0)
A26: Oracle | B26: =COUNTIFS('Datos (calculo)'!$I$2:$I$169,"Oracle",'Datos (calculo)'!$H$2:$H$169,"2026-08") | C26: =IFERROR(COUNTIFS('Datos (calculo)'!$I$2:$I$169,"Oracle",'Datos (calculo)'!$H$2:$H$169,"2026-08")/COUNTIFS('Datos (calculo)'!$H$2:$H$169,"2026-08",'Datos (calculo)'!$F$2:$F$169,">=0"),0) | D26: =IFERROR(ROUND(AVERAGEIFS('Datos (calculo)'!$G$2:$G$169,'Datos (calculo)'!$I$2:$I$169,"Oracle",'Datos (calculo)'!$H$2:$H$169,"2026-08"),1),0) | E26: =IFERROR(COUNTIFS('Datos (calculo)'!$I$2:$I$169,"Oracle",'Datos (calculo)'!$H$2:$H$169,"2026-08",'Datos (calculo)'!$F$2:$F$169,"<24")/COUNTIFS('Datos (calculo)'!$I$2:$I$169,"Oracle",'Datos (calculo)'!$H$2:$H$169,"2026-08"),0)
A27: Taulia | B27: =COUNTIFS('Datos (calculo)'!$I$2:$I$169,"Taulia",'Datos (calculo)'!$H$2:$H$169,"2026-08") | C27: =IFERROR(COUNTIFS('Datos (calculo)'!$I$2:$I$169,"Taulia",'Datos (calculo)'!$H$2:$H$169,"2026-08")/COUNTIFS('Datos (calculo)'!$H$2:$H$169,"2026-08",'Datos (calculo)'!$F$2:$F$169,">=0"),0) | D27: =IFERROR(ROUND(AVERAGEIFS('Datos (calculo)'!$G$2:$G$169,'Datos (calculo)'!$I$2:$I$169,"Taulia",'Datos (calculo)'!$H$2:$H$169,"2026-08"),1),0) | E27: =IFERROR(COUNTIFS('Datos (calculo)'!$I$2:$I$169,"Taulia",'Datos (calculo)'!$H$2:$H$169,"2026-08",'Datos (calculo)'!$F$2:$F$169,"<24")/COUNTIFS('Datos (calculo)'!$I$2:$I$169,"Taulia",'Datos (calculo)'!$H$2:$H$169,"2026-08"),0)
A28: Portal por URL | B28: =COUNTIFS('Datos (calculo)'!$I$2:$I$169,"Portal por URL",'Datos (calculo)'!$H$2:$H$169,"2026-08") | C28: =IFERROR(COUNTIFS('Datos (calculo)'!$I$2:$I$169,"Portal por URL",'Datos (calculo)'!$H$2:$H$169,"2026-08")/COUNTIFS('Datos (calculo)'!$H$2:$H$169,"2026-08",'Datos (calculo)'!$F$2:$F$169,">=0"),0) | D28: =IFERROR(ROUND(AVERAGEIFS('Datos (calculo)'!$G$2:$G$169,'Datos (calculo)'!$I$2:$I$169,"Portal por URL",'Datos (calculo)'!$H$2:$H$169,"2026-08"),1),0) | E28: =IFERROR(COUNTIFS('Datos (calculo)'!$I$2:$I$169,"Portal por URL",'Datos (calculo)'!$H$2:$H$169,"2026-08",'Datos (calculo)'!$F$2:$F$169,"<24")/COUNTIFS('Datos (calculo)'!$I$2:$I$169,"Portal por URL",'Datos (calculo)'!$H$2:$H$169,"2026-08"),0)
A29: Otros | B29: 3 | C29: =IFERROR(B29/COUNTIFS('Datos (calculo)'!$H$2:$H$169,"2026-08",'Datos (calculo)'!$F$2:$F$169,">=0"),0) | D29: 6.5 | E29: 0.667
A30: TOTAL | B30: =COUNTIFS('Datos (calculo)'!$H$2:$H$169,"2026-08",'Datos (calculo)'!$F$2:$F$169,">=0") | C30: =IFERROR(B30/COUNTIFS('Datos (calculo)'!$H$2:$H$169,"2026-08",'Datos (calculo)'!$F$2:$F$169,">=0"),0) | D30: =ROUND(AVERAGEIF('Datos (calculo)'!$H$2:$H$169,"2026-08",'Datos (calculo)'!$G$2:$G$169),1) | E30: =IFERROR(COUNTIFS('Datos (calculo)'!$H$2:$H$169,"2026-08",'Datos (calculo)'!$F$2:$F$169,"<24")/COUNTIFS('Datos (calculo)'!$H$2:$H$169,"2026-08",'Datos (calculo)'!$F$2:$F$169,">=0"),0)
A31: Portales normalizados (Ariba/ARIBA/ariba → Ariba, etc.). Fila 'Otros' agrupa portales de 1 upload.

Sheet Form Responses
A1: Message link | B1: Invoice Number | C1: Invoice Amount | D1: Portal Name or Link | E1: PO Number | F1: Special instructions / notes | G1: Submitted By | H1: Timestamp | I1: Status | J1: Emoji | K1: Assignment Trigger | L1: Collector assigned | M1: Message Timestamp | N1: Resolution Time
A2: https://qualtrics.slack.com/archives/C0A4LNX9SKW/p1766438869224269 | B2: test | C2: test | D2: test | E2: t | F2: t | G2: Alejandra Mendoza | H2: 46013.894 | I2: white_check_mark | J2: ✅ | K2: @alejandram | N2: #NUM!
A3: https://qualtrics.slack.com/archives/C02KP7NE6FP/p1780429636081279 | B3: QILNEW1915 | C3: 4970 | D3: BMW portal | E3: F495QVF | G3: Alejandra Mendoza | H3: 46175.574 | I3: white_check_mark | J3: ✅ | K3: @dreimers | L3: @dreimers | M3: 46176.467 | N3: 0 days 21 hrs
A4: https://qualtrics.slack.com/archives/C02KP7NE6FP/p1780504068556039 | B4: INV00020111 | C4: 1,892,527.00 AUD | D4: Ariba | E4: 3233945 | F4: Hi Diego, could you please help me with this upload? Thanks! | G4: Daniela Gomez Viscaino | H4: 46176.435 | I4: white_check_mark | J4: ✅ | K4: @dreimers | L4: @dreimers | M4: 46176.566 | N4: 0 days 3 hrs
A5: https://qualtrics.slack.com/archives/C02KP7NE6FP/p1780506681567439 | B5: Not Generated | C5: EUR 5,000.00 | D5: http://chorus-pro.gouv.fr | E5: 4500474677 | F5: SFDC Account: https://qualtrics.lightning.force.com/lightning/r/Account__c/0015000000kh2e6AAA/view SFDC Opp/Quote: https://qualtrics.lightning.force.com/lightning/r/Opportunity/006VH00000QU1FpYAL/view Request Details: Hi Team, Once the invoice is issued (SO case already created 🤓!), could you kindly manage the portal upload? Info: 1. Portal: Chorus Pro (http://chorus-pro.gouv.fr) 2. SIRET number: 93823061200013 3. Legal commitment number (PO number): 4500474677 AS:ZZ_C89C4CE975D948F8 | G5: Kaushal Hogade | H5: 46176.463 | I5: white_check_mark | J5: ✅ | K5: @dreimers | L5: @dreimers | M5: 46177.526 | N5: 1 days 1 hrs
A6: https://qualtrics.slack.com/archives/C02KP7NE6FP/p1780515629982839 | B6: INV00019964 | C6: 135239 | D6: Coupa | E6: MPO106786 | G6: Daniela Gomez Viscaino | H6: 46176.569 | I6: white_check_mark | J6: ✅ | K6: @dreimers | L6: @dreimers | M6: 46177.513 | N6: 0 days 22 hrs
A7: https://qualtrics.slack.com/archives/C02KP7NE6FP/p1780607713987399 | B7: 469020 | C7: 9038.14 | D7: Ariba | E7: PO604178 | F7: Hi team! Could please submit this invoice to the Ariba portal? If the invoice has been submitted, please just confirm, as the customer is not seeing the invoice. Thanks in advance! | G7: Maria Granja | H7: 46177.634 | I7: white_check_mark | J7: ✅ | K7: @dreimers | L7: @dreimers | M7: 46178.419 | N7: 0 days 18 hrs
A8: https://qualtrics.slack.com/archives/C02KP7NE6FP/p1780635236655159 | B8: 468868 | C8: 12630 | D8: Ariba | E8: PO3286327 | F8: Hi team, can you please try re-uploading the attached invoice to Ariba? The client is encountering an error on their end (screenshot attached). It looks like there was an issue with the file.Can you please advise on how we can troubleshoot this error? Thank you! | G8: Ashley Hudson | H8: 46177.952 | I8: white_check_mark | J8: ✅ | K8: @dreimers | L8: @dreimers | M8: 46197.54 | N8: 19 days 14 hrs
A9: https://qualtrics.slack.com/archives/C02KP7NE6FP/p1780644026629379 | B9: INV00020070 / INV00020071 / INV00020069 / 469136 | C9: See below | D9: Taulia | E9: See below | F9: See replies for PO and amount details. Thank you! | G9: Ashley Hudson | H9: 46178.051 | I9: white_check_mark | J9: ✅ | K9: @dreimers | L9: @dreimers | M9: 46178.564 | N9: 0 days 12 hrs
A10: https://qualtrics.slack.com/archives/C02KP7NE6FP/p1780688144531449 | C10: 8.5K | D10: Ariba | F10: We have an opp we can't process because we are waiting for the PO#. Client said that the PO# is already in Ariba. Can you please look into Ariba and see if there is a PO for that amount ($8500 USD)?. If there is one, can you share it so I can update the PO is SFDC and process the opp? | G10: Pamella Covarrubias | H10: 46178.565 | I10: white_check_mark | J10: ✅ | K10: @edeanda | L10: @dreimers | M10: 46178.607 | N10: 0 days 0 hrs
A11: https://qualtrics.slack.com/archives/C02KP7NE6FP/p1780690569170249 | B11: 466580 | C11: 5198.48 | D11: https://www.vendors.gov.sg/ | E11: 6000241132 | F11: Hello Team, The customer requested for e-invoice via vendors@gov for PO #6000241132 under vendor ID: Y286982. I have attached the guide for e-invoice submission via vendors@gov for your reference | G11: Nikhil Anjikar | H11: 46178.588 | I11: white_check_mark | J11: ✅ | K11: @nanjikar | L11: @dreimers | M11: 46183.649 | N11: 5 days 1 hrs
A12: https://qualtrics.slack.com/archives/C02KP7NE6FP/p1780948263572659 | B12: INV00020293 | C12: Google | D12: Google | E12: 4100794478 | F12: Hi team, can you please upload this invoice? Thanks | G12: Daniela Gomez Viscaino | H12: 46181.576 | I12: white_check_mark | J12: ✅ | K12: @dreimers | L12: @dreimers | M12: 46182.331 | N12: 0 days 18 hrs
A13: https://qualtrics.slack.com/archives/C02KP7NE6FP/p1781116613992809 | B13: unknown | C13: unknown | D13: Coupa | E13: 491884 | F13: Hi team! We received a ticket from the client "Coppel, S.A. de C.V." requesting the following: "Could you help us by uploading the documents so we can continue with the receipt and payment process? Invoice, XML, proof of ownership document, goods receipt form signed by the supplier and the Coppel user department, and the supplementary questionnaire. Regards.." No invoice was attached for reference and the PO# is not linked to any Opp in SFDC. Could you track it in the portal? | G13: Eduardo Rivera | H13: 46183.523 | I13: white_check_mark | J13: ✅ | K13: @dreimers | L13: @dreimers | M13: 46183.612 | N13: 0 days 2 hrs
A14: https://qualtrics.slack.com/archives/C02KP7NE6FP/p1781130261976739 | B14: 470660 | C14: 412500 | D14: Coupa | E14: 8005355996 | F14: Client was setup in Coupa under Procter & Gamble - 0015285300.CL | G14: Jose Novelo | H14: 46183.683 | I14: white_check_mark | J14: ✅ | K14: @dreimers | L14: @dreimers | M14: 46197.545 | N14: 13 days 20 hrs
A15: https://qualtrics.slack.com/archives/C02KP7NE6FP/p1781130682061729 | B15: 470678 | C15: 194850 | D15: Awrostamani Portal | E15: 389168 - 0 | G15: Jose Novelo | H15: 46183.688 | I15: white_check_mark | J15: ✅ | K15: @dreimers | L15: @dreimers | M15: 46185.422 | N15: 1 days 17 hrs
A16: https://qualtrics.slack.com/archives/C02KP7NE6FP/p1781242703251409 | B16: 462239 | D16: Coupa | F16: Hi Team, client has requested we void the second entry here as it is invalid/duplicate. Please access platform and adjust | G16: Saiyon Tanaka | H16: 46184.984 | I16: white_check_mark | J16: ✅ | K16: @dreimers | L16: @dreimers | M16: 46185.489 | N16: 0 days 12 hrs
A17: https://qualtrics.slack.com/archives/C02KP7NE6FP/p1781288921850609 | B17: INV00020633 | C17: 557399.09 | D17: Ariba | E17: 4500318350 | F17: Hi Diego, could you please help me uploading this invoice. Thanks! | G17: Daniela Gomez Viscaino | H17: 46185.519 | I17: white_check_mark | J17: ✅ | K17: @dreimers | L17: @dreimers | M17: 46197.547 | N17: 12 days 0 hrs
A18: https://qualtrics.slack.com/archives/C02KP7NE6FP/p1781514317663729 | B18: #464499 | C18: SGD $35,625.00 | D18: Ariba | E18: n.a. | F18: The invoice uploaded in Ariba was incorrect. Could you please upload the attached invoice. Please attention to liyi_cheong@sats.com.sg as verifier. | G18: Emma Günther | H18: 46188.126 | I18: white_check_mark | J18: ✅ | K18: @alejandram | L18: @dreimers | M18: 46192.575 | N18: 4 days 10 hrs
A19: https://qualtrics.slack.com/archives/C02KP7NE6FP/p1781540763692849 | B19: INV00020140 | C19: 1099.74 | D19: PEPPOL | E19: 26035603 | G19: Fabrizio Rico del Mazo | H19: 46188.434 | I19: white_check_mark | J19: ✅ | K19: @dreimers | L19: @dreimers | M19: 46197.551 | N19: 9 days 2 hrs
A20: https://qualtrics.slack.com/archives/C02KP7NE6FP/p1781559825463709 | B20: INV00020695 | C20: INV00020695 | D20: Ariba | E20: 4100813377 | G20: Daniela Gomez Viscaino | H20: 46188.655 | I20: white_check_mark | J20: ✅ | K20: @aprilj | L20: @aprilj | M20: 46189.315 | N20: 0 days 15 hrs
A21: https://qualtrics.slack.com/archives/C02KP7NE6FP/p1781560246081169 | B21: INV00020722 | C21: 10500 | D21: Ariba | E21: 4100811071 | G21: Daniela Gomez Viscaino | H21: 46188.659 | I21: white_check_mark | J21: ✅ | K21: @aprilj | L21: @aprilj | M21: 46189.318 | N21: 0 days 15 hrs
A22: https://qualtrics.slack.com/archives/C02KP7NE6FP/p1781561118124499 | B22: INV00020373 | C22: 209034 | D22: Coupa | E22: 374271 | G22: Daniela Gomez Viscaino | H22: 46188.67 | I22: white_check_mark | J22: ✅ | K22: @dreimers | L22: @aprilj | M22: 46189.331 | N22: 0 days 15 hrs
A23: https://qualtrics.slack.com/archives/C02KP7NE6FP/p1781625323936489 | B23: 470845 | C23: 28000 | D23: https://suppliers.qf.org.qa/ | E23: QF-PO-46594-HOP | F23: You may now upload the related invoice electronically by using the QF I-Supplier Portal at https://suppliers.qf.org.qa/ In case of any issues during the submission process, kindly contact QF Procurement Relations procurementrelations@qf.org.qa to address your concern. | G23: Fabrizio Rico del Mazo | H23: 46189.413 | I23: white_check_mark | J23: ✅ | K23: @dreimers | L23: @dreimers | M23: 46202.489 | N23: 13 days 1 hrs
A24: https://qualtrics.slack.com/archives/C02KP7NE6FP/p1781634749343139 | B24: INV00020793 | C24: 31752 | D24: Microsoft | E24: 101669908 | G24: Diego Cué Vázquez | H24: 46189.522 | I24: white_check_mark | J24: ✅ | K24: @dreimers | L24: @dreimers | M24: 46190.381 | N24: 0 days 20 hrs
A25: https://qualtrics.slack.com/archives/C02KP7NE6FP/p1781635224453029 | B25: INV00020795 | C25: 32760 | D25: Microsoft | E25: 101626136 | G25: Diego Cué Vázquez | H25: 46189.528 | I25: white_check_mark | J25: ✅ | K25: @dreimers | L25: @dreimers | M25: 46190.38 | N25: 0 days 20 hrs
A26: https://qualtrics.slack.com/archives/C02KP7NE6FP/p1781725717115399 | B26: INV00020920 | C26: 200410 | D26: COUPA | E26: 4614038 | G26: Andrea Juarez | H26: 46190.575 | I26: white_check_mark | J26: ✅ | K26: @dreimers | L26: @dreimers | M26: 46190.583 | N26: 0 days 0 hrs
A27: https://qualtrics.slack.com/archives/C02KP7NE6FP/p1781797607782699 | B27: INV00020933 | C27: 161256.8 | D27: ARIBA | E27: 4520248300 | G27: Andrea Juarez | H27: 46191.407 | I27: white_check_mark | J27: ✅ | K27: @dreimers | L27: @dreimers | M27: 46191.427 | N27: 0 days 0 hrs
A28: https://qualtrics.slack.com/archives/C02KP7NE6FP/p1781804512723809 | B28: 470501 | C28: 2080 | D28: transcepta | E28: BB02012207 | G28: Erika Sorrell | H28: 46191.486 | I28: white_check_mark | J28: ✅ | K28: @aprilj | L28: @aprilj | M28: 46191.562 | N28: 0 days 1 hrs
A29: https://qualtrics.slack.com/archives/C02KP7NE6FP/p1781808178507259 | B29: INV00020607 | C29: 48998 | D29: coupa | E29: 373752 | G29: Alejandro Salazar Copado | H29: 46191.529 | I29: white_check_mark | J29: ✅ | K29: @dreimers | L29: @dreimers | M29: 46191.555 | N29: 0 days 0 hrs
A30: https://qualtrics.slack.com/archives/C02KP7NE6FP/p1781811873820999 | B30: INV00021001 | C30: 27630 | D30: Suppplier connect | E30: 70001688499 | G30: Diego Cué Vázquez | H30: 46191.572 | I30: white_check_mark | J30: ✅ | K30: @dreimers | L30: @dreimers | M30: 46191.607 | N30: 0 days 0 hrs
A31: https://qualtrics.slack.com/archives/C02KP7NE6FP/p1781887412035269 | B31: INV00020899 | C31: 1,768,194.49 USD | D31: Ariba | E31: PO3000364445 | F31: Hi team, can you help me with this upload? thanks | G31: Daniela Gomez Viscaino | H31: 46192.446 | I31: white_check_mark | J31: ✅ | K31: @dreimers | L31: @dreimers | M31: 46197.551 | N31: 5 days 2 hrs
A32: https://qualtrics.slack.com/archives/C02KP7NE6FP/p1781890631636629 | B32: INV00020931 | C32: 63000 | D32: Coupa | E32: 7202278873 | G32: Andrea Juarez | H32: 46192.484 | I32: white_check_mark | J32: ✅ | K32: @dreimers | L32: @dreimers | M32: 46192.532 | N32: 0 days 1 hrs
A33: https://qualtrics.slack.com/archives/C02KP7NE6FP/p1781903380133369 | B33: INV00020933 | C33: 161256.8 | D33: Ariba | E33: 4520248300 | F33: Hi Diego, could you help me with this request please | G33: Daniela Gomez Viscaino | H33: 46192.631 | I33: white_check_mark | J33: ✅ | K33: @dreimers | L33: @dreimers | M33: 46195.41 | N33: 2 days 18 hrs
A34: https://qualtrics.slack.com/archives/C02KP7NE6FP/p1781904191133049 | B34: INV00020931 | C34: 63000 | D34: Coupa | E34: 7202278873 | G34: Daniela Gomez Viscaino | H34: 46192.64 | I34: white_check_mark | J34: ✅ | K34: @dreimers | L34: @dreimers | M34: 46195.422 | N34: 2 days 18 hrs
A35: https://qualtrics.slack.com/archives/C02KP7NE6FP/p1781904352478749 | B35: INV00020793 | C35: 31752 | D35: Microsoft | E35: 101669908 | G35: Daniela Gomez Viscaino | H35: 46192.642 | I35: white_check_mark | J35: ✅ | K35: @dreimers | L35: @dreimers | M35: 46195.443 | N35: 2 days 19 hrs
A36: https://qualtrics.slack.com/archives/C02KP7NE6FP/p1781904683647979 | B36: INV00020920 | C36: 200410 | D36: Coupa | E36: 4614038 | G36: Daniela Gomez Viscaino | H36: 46192.646 | I36: white_check_mark | J36: ✅ | K36: @dreimers | L36: @dreimers | M36: 46195.426 | N36: 2 days 18 hrs
A37: https://qualtrics.slack.com/archives/C02KP7NE6FP/p1781906633040689 | B37: INV00020867 | C37: 20000 | D37: Ariba | E37: 4100803422 | G37: Daniela Gomez Viscaino | H37: 46192.668 | I37: white_check_mark | J37: ✅ | K37: @dreimers | L37: @dreimers | M37: 46195.434 | N37: 2 days 18 hrs
A38: https://qualtrics.slack.com/archives/C02KP7NE6FP/p1782136417315069 | B38: QILNEW2100 | C38: 4815.72 | D38: Chorus Pro | E38: 1513730710 | F38: Hi, the client accidentally deleted the request of upload, could we please reuload the invoice (PO attached) | G38: Yulian Trishch | H38: 46195.326 | I38: white_check_mark | J38: ✅ | K38: @dreimers | L38: @dreimers | M38: 46195.449 | N38: 0 days 2 hrs
A39: https://qualtrics.slack.com/archives/C02KP7NE6FP/p1782240292382289 | B39: INV00020373 | C39: JPY 209,034 | D39: Coupa | E39: 376864 | F39: Please find attached the manually updated invoice with the new PO number requested by the customer. Per Daiki's instructions, please re-upload it to Coupa. Thank you. | G39: Alejandro Salazar Copado | H39: 46196.529 | I39: white_check_mark | J39: ✅ | K39: @dreimers | L39: @dreimers | M39: 46196.544 | N39: 0 days 0 hrs
A40: https://qualtrics.slack.com/archives/C02KP7NE6FP/p1782245205033039 | B40: INV00021485 | C40: 16575 | D40: Ariba | E40: PO2339695 | G40: Daniela Gomez Viscaino | H40: 46196.586 | I40: white_check_mark | J40: ✅ | K40: @dreimers | L40: @dreimers | M40: 46220.591 | N40: 24 days 0 hrs
...

Sheet Nomenclature
A1: Emoji | B1: Meaning
A2: 👀 | B2: Pending review
A3: 🔥 | B3: Priority (>100K)
A4: ❓ | B4: Waiting for info
A5: ✅ | B5: Completed

Sheet Datos (calculo)
A1: Invoice Number | B1: Submitted By | C1: Collector assigned | D1: Submit Timestamp | E1: Resolved Timestamp | F1: Resolution (hrs) | G1: Resolution (dias) | H1: Mes | I1: Portal (norm.)
A2: test | B2: Alejandra Mendoza | D2: 46013.894 | H2: 2025-12 | I2: Sin dato
A3: QILNEW1915 | B3: Alejandra Mendoza | C3: @dreimers | D3: 46175.574 | E3: 46176.467 | F3: 21.4 | G3: 0.9 | H3: 2026-06 | I3: Bmw Portal
A4: INV00020111 | B4: Daniela Gomez Viscaino | C4: @dreimers | D4: 46176.435 | E4: 46176.566 | F4: 3.1 | G4: 0.1 | H4: 2026-06 | I4: Ariba
A5: Not Generated | B5: Kaushal Hogade | C5: @dreimers | D5: 46176.463 | E5: 46177.526 | F5: 25.5 | G5: 1.1 | H5: 2026-06 | I5: Chorus Pro
A6: INV00019964 | B6: Daniela Gomez Viscaino | C6: @dreimers | D6: 46176.569 | E6: 46177.513 | F6: 22.7 | G6: 0.9 | H6: 2026-06 | I6: Coupa
A7: 469020 | B7: Maria Granja | C7: @dreimers | D7: 46177.634 | E7: 46178.419 | F7: 18.8 | G7: 0.8 | H7: 2026-06 | I7: Ariba
A8: 468868 | B8: Ashley Hudson | C8: @dreimers | D8: 46177.952 | E8: 46197.54 | F8: 470.1 | G8: 19.6 | H8: 2026-06 | I8: Ariba
A9: INV00020070 / INV00020071 / INV00020069 / 469136 | B9: Ashley Hudson | C9: @dreimers | D9: 46178.051 | E9: 46178.564 | F9: 12.3 | G9: 0.5 | H9: 2026-06 | I9: Taulia
B10: Pamella Covarrubias | C10: @dreimers | D10: 46178.565 | E10: 46178.607 | F10: 1 | G10: 0 | H10: 2026-06 | I10: Ariba
A11: 466580 | B11: Nikhil Anjikar | C11: @dreimers | D11: 46178.588 | E11: 46183.649 | F11: 121.5 | G11: 5.1 | H11: 2026-06 | I11: Portal por URL
A12: INV00020293 | B12: Daniela Gomez Viscaino | C12: @dreimers | D12: 46181.576 | E12: 46182.331 | F12: 18.1 | G12: 0.8 | H12: 2026-06 | I12: Google
A13: unknown | B13: Eduardo Rivera | C13: @dreimers | D13: 46183.523 | E13: 46183.612 | F13: 2.1 | G13: 0.1 | H13: 2026-06 | I13: Coupa
A14: 470660 | B14: Jose Novelo | C14: @dreimers | D14: 46183.683 | E14: 46197.545 | F14: 332.7 | G14: 13.9 | H14: 2026-06 | I14: Coupa
A15: 470678 | B15: Jose Novelo | C15: @dreimers | D15: 46183.688 | E15: 46185.422 | F15: 41.6 | G15: 1.7 | H15: 2026-06 | I15: Awrostamani Portal
A16: 462239 | B16: Saiyon Tanaka | C16: @dreimers | D16: 46184.984 | E16: 46185.489 | F16: 12.1 | G16: 0.5 | H16: 2026-06 | I16: Coupa
A17: INV00020633 | B17: Daniela Gomez Viscaino | C17: @dreimers | D17: 46185.519 | E17: 46197.547 | F17: 288.7 | G17: 12 | H17: 2026-06 | I17: Ariba
A18: #464499 | B18: Emma Günther | C18: @dreimers | D18: 46188.126 | E18: 46192.575 | F18: 106.8 | G18: 4.4 | H18: 2026-06 | I18: Ariba
A19: INV00020140 | B19: Fabrizio Rico del Mazo | C19: @dreimers | D19: 46188.434 | E19: 46197.551 | F19: 218.8 | G19: 9.1 | H19: 2026-06 | I19: Peppol
A20: INV00020695 | B20: Daniela Gomez Viscaino | C20: @aprilj | D20: 46188.655 | E20: 46189.315 | F20: 15.9 | G20: 0.7 | H20: 2026-06 | I20: Ariba
A21: INV00020722 | B21: Daniela Gomez Viscaino | C21: @aprilj | D21: 46188.659 | E21: 46189.318 | F21: 15.8 | G21: 0.7 | H21: 2026-06 | I21: Ariba
A22: INV00020373 | B22: Daniela Gomez Viscaino | C22: @aprilj | D22: 46188.67 | E22: 46189.331 | F22: 15.9 | G22: 0.7 | H22: 2026-06 | I22: Coupa
... A47: INV00021650 | B47: Maria de Lourdes López Núñez | C47: @dreimers | D47: 46198.49 | E47: 46198.574 | F47: 2 | G47: 0.1 | H47: 2026-06 | I47: Coupa
A48: 470840 | B48: Kaushal Hogade | D48: 46199.163 | E48: 46199.471 | F48: 7.4 | G48: 0.3 | H48: 2026-06 | I48: Chorus Pro
A49: 2D-21801766 | B49: Imanol Martinez | C49: @dreimers | D49: 46199.426 | E49: 46199.488 | F49: 1.5 | G49: 0.1 | H49: 2026-06 | I49: Coupa
A50: INV00021939 | B50: Andrea Juarez | C50: @dreimers | D50: 46201.952 | E50: 46202.547 | F50: 14.3 | G50: 0.6 | H50: 2026-06 | I50: Microsoft
A51: 4500114905 | B51: Eleonora Amarante | C51: @dreimers | D51: 46202.438 | E51: 46202.518 | F51: 1.9 | G51: 0.1 | H51: 2026-06 | I51: Chorus Pro
A52: 471109 | B52: Fabrizio Rico del Mazo | C52: @kburkett | D52: 46202.515 | E52: 46202.621 | F52: 2.5 | G52: 0.1 | H52: 2026-06 | I52: Coupa
A53: INV00021802 | B53: Daniela Gomez Viscaino | C53: @kburkett | D53: 46202.786 | E53: 46202.937 | F53: 3.6 | G53: 0.2 | H53: 2026-06 | I53: Ariba
A54: INV00021701 | B54: Daniela Gomez Viscaino | C54: @kburkett | D54: 46202.788 | E54: 46202.917 | F54: 3.1 | G54: 0.1 | H54: 2026-06 | I54: Coupa
A55: INV00021462 | B55: Daniela Gomez Viscaino | C55: @kburkett | D55: 46202.791 | E55: 46202.933 | F55: 3.4 | G55: 0.1 | H55: 2026-06 | I55: Ariba
A56: INV00021491 | B56: Daniela Gomez Viscaino | C56: @kburkett | D56: 46202.792 | E56: 46202.929 | F56: 3.3 | G56: 0.1 | H56: 2026-06 | I56: Coupa
A57: INV00021769 | B57: Daniela Gomez Viscaino | C57: @kburkett | D57: 46202.794 | E57: 46210.341 | F57: 181.1 | G57: 7.5 | H57: 2026-06 | I57: Coupa
A58: INV00021673 | B58: Ashley Hudson | C58: @kburkett | D58: 46202.822 | E58: 46202.9 | F58: 1.9 | G58: 0.1 | H58: 2026-06 | I58: Taulia
A59: INV00022143 | B59: Daniela Gomez Viscaino | C59: @dreimers | D59: 46203.462 | E59: 46218.473 | F59: 360.3 | G59: 15 | H59: 2026-06 | I59: Ariba
A60: INV00019962 | B60: Elías Chávez Zamorano | C60: @dreimers | D60: 46203.552 | E60: 46204.506 | F60: 22.9 | G60: 1 | H60: 2026-06 | I60: Ariba
... A79: 465391 | B79: George Kahy | C79: @dreimers | D79: 46212.958 | E79: 46213.498 | F79: 13 | G79: 0.5 | H79: 2026-07 | I79: Ariba
B80: Andres Prieto | C80: @dreimers | D80: 46213.661 | E80: 46216.506 | F80: 68.3 | G80: 2.8 | H80: 2026-07 | I80: Sin dato
A81: 471288 | B81: Alejandro Salazar Copado | C81: @dreimers | D81: 46213.682 | E81: 46216.509 | F81: 67.8 | G81: 2.8 | H81: 2026-07 | I81: Ariba
A82: 471302 | B82: Alejandro Salazar Copado | C82: @dreimers | D82: 46216.4 | E82: 46218.468 | F82: 49.6 | G82: 2.1 | H82: 2026-07 | I82: Ariba
...

Sheet Atipicos Agosto (>7 dias)
A1: CASOS ATÍPICOS DE AGOSTO — Resolución mayor a 7 días
A2: 3 uploads de agosto superaron los 7 días.
A4: Invoice Number | B4: Submitted By | C4: Collector assigned | D4: Portal | E4: Submit Timestamp | F4: Resolved Timestamp | G4: Días de resolución
A5: 466580 | B5: Mario Cortés | C5: @dreimers | D5: Www.Vendors.Gov.Sg | E5: 46247.584 | F5: 46266.738 | G5: =(F5-E5)
A6: 398434 | B6: Nathan Smith | C6: @dreimers | D6: Portal por URL | E6: 46237.462 | F6: 46245.386 | G6: =(F6-E6)
A7: 434853 | B7: Nathan Smith | C7: @dreimers | D7: Portal por URL | E7: 46237.464 | F7: 46245.386 | G7: =(F7-E7)
F9: Promedio atípicos: | G9: =ROUND(AVERAGE(G5:G7),1)
