Workbook

Sheet Tesorio Tasks Report
A1: TESORIO TASKS REPORT — Aug - 26
A4: Aug - 26 SUMMARY | D4: RESOLUTION TIME BY MONTH (last 3 months)
A5: Created in month | B5: =COUNTIF('Data (calc)'!$I$2:$I$169,"2026-08") | D5: Month | E5: # Created | F5: Completed | G5: Avg. hours | H5: Avg. days | I5: % same day
A6: Completed (DONE) | B6: =COUNTIFS('Data (calc)'!$I$2:$I$169,"2026-08",'Data (calc)'!$G$2:$G$169,">=0") | D6: Jun - 26 | E6: =COUNTIF('Data (calc)'!$I$2:$I$169,"2026-06") | F6: =COUNTIFS('Data (calc)'!$I$2:$I$169,"2026-06",'Data (calc)'!$G$2:$G$169,">=0") | G6: =IFERROR(ROUND(AVERAGEIF('Data (calc)'!$I$2:$I$169,"2026-06",'Data (calc)'!$G$2:$G$169),1),0) | H6: =IFERROR(ROUND(AVERAGEIF('Data (calc)'!$I$2:$I$169,"2026-06",'Data (calc)'!$H$2:$H$169),1),0) | I6: =IFERROR(COUNTIFS('Data (calc)'!$I$2:$I$169,"2026-06",'Data (calc)'!$G$2:$G$169,"<24")/COUNTIFS('Data (calc)'!$I$2:$I$169,"2026-06",'Data (calc)'!$G$2:$G$169,">=0"),0)
A7: Avg. resolution (days) | B7: =IFERROR(ROUND(AVERAGEIF('Data (calc)'!$I$2:$I$169,"2026-08",'Data (calc)'!$H$2:$H$169),1),0) | D7: Jul - 26 | E7: =COUNTIF('Data (calc)'!$I$2:$I$169,"2026-07") | F7: =COUNTIFS('Data (calc)'!$I$2:$I$169,"2026-07",'Data (calc)'!$G$2:$G$169,">=0") | G7: =IFERROR(ROUND(AVERAGEIF('Data (calc)'!$I$2:$I$169,"2026-07",'Data (calc)'!$G$2:$G$169),1),0) | H7: =IFERROR(ROUND(AVERAGEIF('Data (calc)'!$I$2:$I$169,"2026-07",'Data (calc)'!$H$2:$H$169),1),0) | I7: =IFERROR(COUNTIFS('Data (calc)'!$I$2:$I$169,"2026-07",'Data (calc)'!$G$2:$G$169,"<24")/COUNTIFS('Data (calc)'!$I$2:$I$169,"2026-07",'Data (calc)'!$G$2:$G$169,">=0"),0)
A8: % same day | B8: =IFERROR(COUNTIFS('Data (calc)'!$I$2:$I$169,"2026-08",'Data (calc)'!$G$2:$G$169,"<24")/COUNTIFS('Data (calc)'!$I$2:$I$169,"2026-08",'Data (calc)'!$G$2:$G$169,">=0"),0) | D8: Aug - 26 | E8: =COUNTIF('Data (calc)'!$I$2:$I$169,"2026-08") | F8: =COUNTIFS('Data (calc)'!$I$2:$I$169,"2026-08",'Data (calc)'!$G$2:$G$169,">=0") | G8: =IFERROR(ROUND(AVERAGEIF('Data (calc)'!$I$2:$I$169,"2026-08",'Data (calc)'!$G$2:$G$169),1),0) | H8: =IFERROR(ROUND(AVERAGEIF('Data (calc)'!$I$2:$I$169,"2026-08",'Data (calc)'!$H$2:$H$169),1),0) | I8: =IFERROR(COUNTIFS('Data (calc)'!$I$2:$I$169,"2026-08",'Data (calc)'!$G$2:$G$169,"<24")/COUNTIFS('Data (calc)'!$I$2:$I$169,"2026-08",'Data (calc)'!$G$2:$G$169,">=0"),0)
A9: Pending (TO DO) today | B9: =COUNTIF('Data (calc)'!$B$2:$B$169,"TO DO") | D9: TOTAL | E9: =SUM(E6:E8) | F9: =SUM(F6:F8) | G9: =IFERROR(ROUND(AVERAGEIFS('Data (calc)'!$G$2:$G$169,'Data (calc)'!$I$2:$I$169,">=2026-06"),1),0) | H9: =IFERROR(ROUND(AVERAGEIFS('Data (calc)'!$H$2:$H$169,'Data (calc)'!$I$2:$I$169,">=2026-06"),1),0) | I9: =IFERROR(COUNTIFS('Data (calc)'!$I$2:$I$169,">=2026-06",'Data (calc)'!$G$2:$G$169,"<24")/COUNTIFS('Data (calc)'!$I$2:$I$169,">=2026-06",'Data (calc)'!$G$2:$G$169,">=0"),0)
A10: In progress (WORKING) today | B10: =COUNTIF('Data (calc)'!$B$2:$B$169,"WORKING")
A15: RESOLUTION TIME DISTRIBUTION — Aug - 26 | D15: RESOLUTION TIME BY PRIORITY — Aug - 26
A16: Range | B16: # Tasks | C16: % of total | D16: Priority | E16: # Tasks | F16: % of total | G16: Avg. days | H16: % same day
A17: Same day (< 24 h) | B17: =COUNTIFS('Data (calc)'!$I$2:$I$169,"2026-08",'Data (calc)'!$G$2:$G$169,"<24") | C17: =IFERROR(B17/COUNTIFS('Data (calc)'!$I$2:$I$169,"2026-08",'Data (calc)'!$G$2:$G$169,">=0"),0) | D17: URGENT | E17: =COUNTIFS('Data (calc)'!$C$2:$C$169,"URGENT",'Data (calc)'!$I$2:$I$169,"2026-08",'Data (calc)'!$G$2:$G$169,">=0") | F17: =IFERROR(COUNTIFS('Data (calc)'!$C$2:$C$169,"URGENT",'Data (calc)'!$I$2:$I$169,"2026-08",'Data (calc)'!$G$2:$G$169,">=0")/COUNTIFS('Data (calc)'!$I$2:$I$169,"2026-08",'Data (calc)'!$G$2:$G$169,">=0"),0) | G17: =IFERROR(ROUND(AVERAGEIFS('Data (calc)'!$H$2:$H$169,'Data (calc)'!$C$2:$C$169,"URGENT",'Data (calc)'!$I$2:$I$169,"2026-08"),1),0) | H17: =IFERROR(COUNTIFS('Data (calc)'!$C$2:$C$169,"URGENT",'Data (calc)'!$I$2:$I$169,"2026-08",'Data (calc)'!$G$2:$G$169,"<24")/COUNTIFS('Data (calc)'!$C$2:$C$169,"URGENT",'Data (calc)'!$I$2:$I$169,"2026-08",'Data (calc)'!$G$2:$G$169,">=0"),0)
A18: 1 – 2 days | B18: =COUNTIFS('Data (calc)'!$I$2:$I$169,"2026-08",'Data (calc)'!$G$2:$G$169,">=24",'Data (calc)'!$G$2:$G$169,"<48") | C18: =IFERROR(B18/COUNTIFS('Data (calc)'!$I$2:$I$169,"2026-08",'Data (calc)'!$G$2:$G$169,">=0"),0) | D18: HIGH PRIORITY | E18: =COUNTIFS('Data (calc)'!$C$2:$C$169,"HIGH PRIORITY",'Data (calc)'!$I$2:$I$169,"2026-08",'Data (calc)'!$G$2:$G$169,">=0") | F18: =IFERROR(COUNTIFS('Data (calc)'!$C$2:$C$169,"HIGH PRIORITY",'Data (calc)'!$I$2:$I$169,"2026-08",'Data (calc)'!$G$2:$G$169,">=0")/COUNTIFS('Data (calc)'!$I$2:$I$169,"2026-08",'Data (calc)'!$G$2:$G$169,">=0"),0) | G18: =IFERROR(ROUND(AVERAGEIFS('Data (calc)'!$H$2:$H$169,'Data (calc)'!$C$2:$C$169,"HIGH PRIORITY",'Data (calc)'!$I$2:$I$169,"2026-08"),1),0) | H18: =IFERROR(COUNTIFS('Data (calc)'!$C$2:$C$169,"HIGH PRIORITY",'Data (calc)'!$I$2:$I$169,"2026-08",'Data (calc)'!$G$2:$G$169,"<24")/COUNTIFS('Data (calc)'!$C$2:$C$169,"HIGH PRIORITY",'Data (calc)'!$I$2:$I$169,"2026-08",'Data (calc)'!$G$2:$G$169,">=0"),0)
A19: 2 – 4 days | B19: =COUNTIFS('Data (calc)'!$I$2:$I$169,"2026-08",'Data (calc)'!$G$2:$G$169,">=48",'Data (calc)'!$G$2:$G$169,"<96") | C19: =IFERROR(B19/COUNTIFS('Data (calc)'!$I$2:$I$169,"2026-08",'Data (calc)'!$G$2:$G$169,">=0"),0) | D19: NORMAL | E19: =COUNTIFS('Data (calc)'!$C$2:$C$169,"NORMAL",'Data (calc)'!$I$2:$I$169,"2026-08",'Data (calc)'!$G$2:$G$169,">=0") | F19: =IFERROR(COUNTIFS('Data (calc)'!$C$2:$C$169,"NORMAL",'Data (calc)'!$I$2:$I$169,"2026-08",'Data (calc)'!$G$2:$G$169,">=0")/COUNTIFS('Data (calc)'!$I$2:$I$169,"2026-08",'Data (calc)'!$G$2:$G$169,">=0"),0) | G19: =IFERROR(ROUND(AVERAGEIFS('Data (calc)'!$H$2:$H$169,'Data (calc)'!$C$2:$C$169,"NORMAL",'Data (calc)'!$I$2:$I$169,"2026-08"),1),0) | H19: =IFERROR(COUNTIFS('Data (calc)'!$C$2:$C$169,"NORMAL",'Data (calc)'!$I$2:$I$169,"2026-08",'Data (calc)'!$G$2:$G$169,"<24")/COUNTIFS('Data (calc)'!$C$2:$C$169,"NORMAL",'Data (calc)'!$I$2:$I$169,"2026-08",'Data (calc)'!$G$2:$G$169,">=0"),0)
A20: 4 – 7 days | B20: =COUNTIFS('Data (calc)'!$I$2:$I$169,"2026-08",'Data (calc)'!$G$2:$G$169,">=96",'Data (calc)'!$G$2:$G$169,"<168") | C20: =IFERROR(B20/COUNTIFS('Data (calc)'!$I$2:$I$169,"2026-08",'Data (calc)'!$G$2:$G$169,">=0"),0) | D20: TOTAL | E20: =COUNTIFS('Data (calc)'!$I$2:$I$169,"2026-08",'Data (calc)'!$G$2:$G$169,">=0") | F20: 100% | G20: =IFERROR(ROUND(AVERAGEIF('Data (calc)'!$I$2:$I$169,"2026-08",'Data (calc)'!$H$2:$H$169),1),0) | H20: =IFERROR(COUNTIFS('Data (calc)'!$I$2:$I$169,"2026-08",'Data (calc)'!$G$2:$G$169,"<24")/COUNTIFS('Data (calc)'!$I$2:$I$169,"2026-08",'Data (calc)'!$G$2:$G$169,">=0"),0)
A21: More than 7 days | B21: =COUNTIFS('Data (calc)'!$I$2:$I$169,"2026-08",'Data (calc)'!$G$2:$G$169,">=168") | C21: =IFERROR(B21/COUNTIFS('Data (calc)'!$I$2:$I$169,"2026-08",'Data (calc)'!$G$2:$G$169,">=0"),0)
A22: TOTAL | B22: =SUM(B17:B21) | C22: =IFERROR(B22/COUNTIFS('Data (calc)'!$I$2:$I$169,"2026-08",'Data (calc)'!$G$2:$G$169,">=0"),0)

Sheet Data (calc)
A1: Invoice Number | B1: Status | C1: Priority | D1: Assigned by | E1: Created At | F1: Completed At | G1: Resolution (hrs) | H1: Resolution (days) | I1: Month (created) | J1: Days open
A2: INV00021679 | B2: TO DO | C2: NORMAL | D2: Raúl Pérez | E2: 46243.956 | I2: 2026-08 | J2: 24
A3: INV00024992 | B3: DONE | C3: NORMAL | D3: Fernando Anaya | E3: 46252.644 | F3: 46252.742 | G3: 2.3 | H3: 0.1 | I3: 2026-08
A4: INV00021985 | B4: DONE | C4: NORMAL | D4: Erika Sorrell | E4: 46247.618 | F4: 46247.852 | G4: 5.6 | H4: 0.2 | I4: 2026-08
A5: INV00021750 | B5: DONE | C5: NORMAL | D5: Fernanda Sánchez | E5: 46230.809 | F5: 46230.863 | G5: 1.3 | H5: 0.1 | I5: 2026-07
A6: 468465 | B6: DONE | C6: NORMAL | D6: Erika Sorrell | E6: 46225.857 | F6: 46227.864 | G6: 48.2 | H6: 2 | I6: 2026-07
A7: 467985 | B7: DONE | C7: NORMAL | D7: Erika Sorrell | E7: 46227.807 | F7: 46227.841 | G7: 0.8 | H7: 0 | I7: 2026-07
A8: INV00022406 | B8: DONE | C8: NORMAL | D8: Erika Sorrell | E8: 46226.845 | F8: 46227.829 | G8: 23.6 | H8: 1 | I8: 2026-07
A9: 465369 | B9: DONE | C9: NORMAL | D9: Erika Sorrell | E9: 46224.865 | F9: 46225.777 | G9: 21.9 | H9: 0.9 | I9: 2026-07
A10: INV00022414 | B10: DONE | C10: NORMAL | D10: Fernanda Sánchez | E10: 46225.704 | F10: 46225.729 | G10: 0.6 | H10: 0 | I10: 2026-07
A11: 470131 | B11: DONE | C11: NORMAL | D11: Erika Sorrell | E11: 46224.854 | F11: 46225.72 | G11: 20.8 | H11: 0.9 | I11: 2026-07
A12: INV00020505 | B12: DONE | C12: NORMAL | D12: Erika Sorrell | E12: 46219.85 | F12: 46220.843 | G12: 23.8 | H12: 1 | I12: 2026-07
A13: INV00022115 | B13: DONE | C13: NORMAL | D13: Erika Sorrell | E13: 46218.873 | F13: 46219.761 | G13: 21.3 | H13: 0.9 | I13: 2026-07
A14: 468465 | B14: DONE | C14: NORMAL | D14: Erika Sorrell | E14: 46216.557 | F14: 46216.812 | G14: 6.1 | H14: 0.3 | I14: 2026-07
... A18: 469706 | B18: DONE | C18: HIGH PRIORITY | D18: Asito Chucuan ✨ | E18: 46182.733 | F18: 46183.827 | G18: 26.3 | H18: 1.1 | I18: 2026-06
A19: INV00024918 | B19: TO DO | C19: NORMAL | D19: Erika Sorrell | E19: 46267.52 | I19: 2026-09 | J19: 0
A20: INV00026378 | B20: TO DO | C20: NORMAL | D20: Julieta Partido | E20: 46267.763 | I20: 2026-09 | J20: 0
B21: TO DO | C21: URGENT | D21: Ana Paula De la Vega | E21: 46266.678 | I21: 2026-09 | J21: 1
A22: INV00022230 | B22: TO DO | C22: URGENT | D22: Ana Paula De la Vega | E22: 46266.68 | I22: 2026-09 | J22: 1
A23: INV00027359 | B23: TO DO | C23: URGENT | D23: Ana Paula De la Vega | E23: 46266.711 | I23: 2026-09 | J23: 1
A24: INV00025992 | B24: DONE | C24: NORMAL | D24: Yoseline Pineda | E24: 46265.631 | F24: 46266.077 | G24: 10.7 | H24: 0.4 | I24: 2026-08
A25: 470131 | B25: DONE | C25: NORMAL | D25: Erika Sorrell | E25: 46261.831 | F25: 46262.016 | G25: 4.4 | H25: 0.2 | I25: 2026-08
A26: INV00025969 | B26: DONE | C26: NORMAL | D26: Alberto Mirón 🦅 | E26: 46261.81 | F26: 46262.015 | G26: 4.9 | H26: 0.2 | I26: 2026-08
A27: INV00024074 | B27: DONE | C27: NORMAL | D27: Eduardo Paredes | E27: 46261.771 | F27: 46262.01 | G27: 5.7 | H27: 0.2 | I27: 2026-08
A28: INV00022114 | B28: DONE | C28: NORMAL | D28: Eduardo Paredes | E28: 46261.734 | F28: 46262.006 | G28: 6.5 | H28: 0.3 | I28: 2026-08
A29: INV00022418 | B29: DONE | C29: NORMAL | D29: Eduardo Paredes | E29: 46261.622 | F29: 46261.995 | G29: 8.9 | H29: 0.4 | I29: 2026-08
A30: INV00027122 | B30: DONE | C30: NORMAL | D30: Diana Escobar | E30: 46262.918 | F30: 46263.001 | G30: 2 | H30: 0.1 | I30: 2026-08
A31: INV00024287 | B31: DONE | C31: NORMAL | D31: Diana Escobar | E31: 46261.64 | F31: 46261.998 | G31: 8.6 | H31: 0.4 | I31: 2026-08
A32: INV00021518 | B32: DONE | C32: NORMAL | D32: Roberto Vázquez | E32: 46261.598 | F32: 46261.991 | G32: 9.4 | H32: 0.4 | I32: 2026-08
A33: INV00022167 | B33: DONE | C33: HIGH PRIORITY | D33: Yoseline Pineda | E33: 46248.631 | F33: 46262.994 | G33: 344.7 | H33: 14.4 | I33: 2026-08
A34: INV00025516 | B34: DONE | C34: NORMAL | D34: Roberto Vázquez | E34: 46260.831 | F34: 46262.048 | G34: 29.2 | H34: 1.2 | I34: 2026-08
A35: INV00023001 | B35: DONE | C35: HIGH PRIORITY | D35: Efraín Córdova | E35: 46261.93 | F35: 46262.018 | G35: 2.1 | H35: 0.1 | I35: 2026-08
... A37: INV00022364 | B37: DONE | C37: NORMAL | D37: Erika Sorrell | E37: 46259.607 | F37: 46260.08 | G37: 11.4 | H37: 0.5 | I37: 2026-08
A38: INV00026412 | B38: DONE | C38: NORMAL | E38: 46258.945 | F38: 46258.947 | G38: 0 | H38: 0 | I38: 2026-08
A39: INV00025207 | B39: WORKING | C39: NORMAL | D39: Alberto Mirón 🦅 | E39: 46254.599 | I39: 2026-08 | J39: 13
A40: 470261 | B40: DONE | C40: HIGH PRIORITY | D40: Marco Guadarrama | E40: 46255.823 | F40: 46258.975 | G40: 75.6 | H40: 3.2 | I40: 2026-08
A41: INV00023786 | B41: DONE | C41: NORMAL | D41: Alberto Mirón 🦅 | E41: 46255.844 | F41: 46259.991 | G41: 99.5 | H41: 4.1 | I41: 2026-08
A42: INV00024048 | B42: DONE | C42: NORMAL | E42: 46253.823 | F42: 46254.95 | G42: 27 | H42: 1.1 | I42: 2026-08
A43: INV00025585 | B43: DONE | C43: NORMAL | D43: Fernanda Sánchez | E43: 46252.789 | F43: 46254.948 | G43: 51.8 | H43: 2.2 | I43: 2026-08
A44: INV00025652 | B44: DONE | C44: NORMAL | D44: Alberto Mirón 🦅 | E44: 46252.71 | F44: 46254.946 | G44: 53.7 | H44: 2.2 | I44: 2026-08
...

Sheet Open & In Progress
A1: OPEN TASKS — Pending (TO DO) and In Progress (WORKING)
A3: Invoice Number | B3: Status | C3: Priority | D3: Assigned by | E3: Created At | F3: Days open
A4: SV540 | B4: WORKING | C4: NORMAL | D4: Israel Illescas | E4: 46223.758 | F4: 44
A5: INV00023791 | B5: WORKING | C5: NORMAL | D5: Yoseline Pineda | E5: 46230.655 | F5: 37
A6: INV00021679 | B6: TO DO | C6: NORMAL | D6: Raúl Pérez | E6: 46243.956 | F6: 24
A7: INV00025207 | B7: WORKING | C7: NORMAL | D7: Alberto Mirón 🦅 | E7: 46254.599 | F7: 13
A8: INV00022230 | B8: TO DO | C8: URGENT | D8: Ana Paula De la Vega | E8: 46266.68 | F8: 1
B9: TO DO | C9: URGENT | D9: Ana Paula De la Vega | E9: 46266.678 | F9: 1
A10: INV00027359 | B10: TO DO | C10: URGENT | D10: Ana Paula De la Vega | E10: 46266.711 | F10: 1
A11: INV00024918 | B11: TO DO | C11: NORMAL | D11: Erika Sorrell | E11: 46267.52 | F11: 0
A12: INV00026378 | B12: TO DO | C12: NORMAL | D12: Julieta Partido | E12: 46267.763 | F12: 0

Sheet Slow Tasks Aug - 26 (>7d)
A1: Aug - 26 TASKS RESOLVED IN MORE THAN 7 DAYS
A3: Invoice Number | B3: Priority | C3: Assigned by | D3: Created At | E3: Completed At | F3: Resolution days
A4: INV00022167 | B4: HIGH PRIORITY | C4: Yoseline Pineda | D4: 46248.631 | E4: 46262.994 | F4: =(E4-D4)
A5: INV00022435 | B5: NORMAL | C5: Eduardo Paredes | D5: 46239.879 | E5: 46248.737 | F5: =(E5-D5)
